Workbook

Sheet Resumo
A1: 25-
B9: Клиент | F9: Matthew Renier
B11: Местоположение | F11: Das Gaivotas, Mata Porcas, Praia da Luz
B13: Описание работ
B15: Общая площадь застройки (м²) | F15: 392.8
B17: Прочее (цоколь, бассейн, пристройки, стены): | F17: 782.27
B19: Бассейн (м²) | F19: 100
B21: Дата | F21: 45812
B23: АРТ º | D23: ОПИСАНИЕ РАБОТ | J23: ИТОГО ПО РАЗДЕЛУ | L23: СТОИМОСТЬ (м2)
B25: ='Orcamento RU'!A4 -> 1 | D25: ='Orcamento RU'!B4 -> СТРОИТЕЛЬНАЯ ПЛОЩАДКА | J25: ='Orcamento RU'!C4 -> 173610.4 | L25: =+J25/$F$15 -> 441.98167
B26: ='Orcamento RU'!A10 -> 2.1 | D26: ='Orcamento RU'!B10 -> КАМЕННАЯ КЛАДКА И ЛЁГКИЕ ОГРАЖДАЮЩИЕ КОНСТРУКЦИИ | J26: ='Orcamento RU'!C10 -> 27737.99 | L26: =+J26/$F$15 -> 70.616064
B27: ='Orcamento RU'!A42 -> 2.2 | D27: ='Orcamento RU'!B42 -> КАМЕННЫЕ ИЗДЕЛИЯ | J27: ='Orcamento RU'!C42 -> 1453.17 | L27: =+J27/$F$15 -> 3.6995163
B28: ='Orcamento RU'!A68 -> 2.3 | D28: ='Orcamento RU'!B68 -> ГИДРОИЗОЛЯЦИЯ И ТЕПЛОИЗОЛЯЦИЯ | J28: ='Orcamento RU'!C68 -> 23753.39 | L28: =+J28/$F$15 -> 60.47197
B29: ='Orcamento RU'!A114 -> 2.4 | D29: ='Orcamento RU'!B114 -> КРОВЛЯ | J29: ='Orcamento RU'!C114 -> 60033.74 | L29: =+J29/$F$15 -> 152.83539
B30: ='Orcamento RU'!A124 -> 2.5 | D30: ='Orcamento RU'!B124 -> ОТДЕЛКА ПОТОЛКОВ | J30: ='Orcamento RU'!C124 -> 15456.87 | L30: =+J30/$F$15 -> 39.350484
B31: ='Orcamento RU'!A142 -> 2.6 | D31: ='Orcamento RU'!B142 -> ОТДЕЛКА СТЕН | J31: ='Orcamento RU'!C142 -> 90725.32 | L31: =+J31/$F$15 -> 230.97077
B32: ='Orcamento RU'!A174 -> 2.7 | D32: ='Orcamento RU'!B174 -> ОТДЕЛКА ПОЛОВ И ПЛИНТУСОВ | J32: ='Orcamento RU'!C174 -> 125744.31 | L32: =+J32/$F$15 -> 320.12299
B33: ='Orcamento RU'!A220 -> 2.8 | D33: ='Orcamento RU'!B220 -> СТОЛЯРНЫЕ РАБОТЫ | J33: ='Orcamento RU'!C220 -> 93859.78 | L33: =+J33/$F$15 -> 238.95056
B34: ='Orcamento RU'!A354 -> 2.9 | D34: ='Orcamento RU'!B354 -> МЕТАЛЛОКОНСТРУКЦИИ И ОКОННЫЕ РАМЫ | J34: ='Orcamento RU'!C354 -> 279339.11 | L34: =+J34/$F$15 -> 711.14845
B35: ='Orcamento RU'!A520 -> 2.1 | D35: ='Orcamento RU'!B520 -> САНТЕХНИЧЕСКОЕ ОБОРУДОВАНИЕ | J35: ='Orcamento RU'!C520 -> 56234.54 | L35: =+J35/$F$15 -> 143.16329
B36: ='Orcamento RU'!A590 -> 2.11 | D36: ='Orcamento RU'!B590 -> ОБОРУДОВАНИЕ КУХНИ И ПРАЧЕЧНОЙ | J36: ='Orcamento RU'!C590 -> 19361 | L36: =+J36/$F$15 -> 49.289715
B37: ='Orcamento RU'!A638 -> 2.12 | D37: ='Orcamento RU'!B638 -> ПРОЧЕЕ | J37: ='Orcamento RU'!C638 -> 34068.69 | L37: =+J37/$F$15 -> 86.732918
B38: ='Orcamento RU'!A698 -> 2.13 | D38: ='Orcamento RU'!B698 -> БЛАГОУСТРОЙСТВО УЧАСТКА | J38: ='Orcamento RU'!C698 -> 75835.91 | L38: =+J38/$F$15 -> 193.06494
B39: ='Orcamento RU'!A749 -> 1 | D39: ='Orcamento RU'!B749 -> ЗЕМЛЯНЫЕ РАБОТЫ | J39: ='Orcamento RU'!C749 -> 51415.45 | L39: =+J39/$F$15 -> 130.89473
B40: ='Orcamento RU'!A761 -> 2 | D40: ='Orcamento RU'!B761 -> ФУНДАМЕНТ И НЕСУЩИЕ КОНСТРУКЦИИ | J40: ='Orcamento RU'!C761 -> 558392.25 | L40: =+J40/$F$15 -> 1421.5689
B41: ='Orcamento RU'!A1043 -> 3 | D41: ='Orcamento RU'!B1043 -> ВНУТРЕННЯЯ СЕТЬ ВОДОСНАБЖЕНИЯ, БАССЕЙН И ВОДНЫЕ ЗЕРКАЛА | J41: ='Orcamento RU'!C1043 -> 40338.6 | L41: =+J41/$F$15 -> 102.69501
B42: ='Orcamento RU'!A1166 -> 4 | D42: ='Orcamento RU'!B1166 -> ВНУТРЕННЯЯ СЕТЬ БЫТОВЫХ И ДОЖДЕВЫХ СТОЧНЫХ ВОД | J42: ='Orcamento RU'!C1166 -> 74220.75 | L42: =+J42/$F$15 -> 188.95303
B43: ='Orcamento RU'!A1299 -> 5 | D43: ='Orcamento RU'!B1299 -> ГАЗОВАЯ СЕТЬ | J43: ='Orcamento RU'!C1299 -> 2768.18 | L43: =+J43/$F$15 -> 7.0473014
B44: ='Orcamento RU'!A1321 -> 6 | D44: ='Orcamento RU'!B1321 -> ПОСТАВКА И МОНТАЖ ОБОРУДОВАНИЯ И СИСТЕМ КОНДИЦИОНИРОВАНИЯ И ПРОИЗВОДСТВА ГОРЯЧЕЙ САНИТАРНОЙ ВОДЫ | J44: ='Orcamento RU'!C1321 -> 181241 | L44: =+J44/$F$15 -> 461.40784
B45: ='Orcamento RU'!A1543 -> 7 | D45: ='Orcamento RU'!B1543 -> ЭЛЕКТРИЧЕСКАЯ СЕТЬ | J45: ='Orcamento RU'!C1543 -> 213667.64 | L45: =+J45/$F$15 -> 543.96039
B46: ='Orcamento RU'!A2127 -> 8 | D46: ='Orcamento RU'!B2127 -> ТЕЛЕКОММУНИКАЦИОННЫЕ УСТАНОВКИ | J46: ='Orcamento RU'!C2127 -> 14218.6 | L46: =+J46/$F$15 -> 36.198065
B47: ='Orcamento RU'!A2206 -> 1.1 | D47: ='Orcamento RU'!B2206 -> ПОДГОТОВИТЕЛЬНЫЕ РАБОТЫ | J47: ='Orcamento RU'!C2206 -> 4600 | L47: =+J47/$F$15 -> 11.710794
B48: ='Orcamento RU'!A2217 -> 1.2 | D48: ='Orcamento RU'!B2217 -> ЗЕМЛЯНЫЕ РАБОТЫ | J48: ='Orcamento RU'!C2217 -> 22379.02 | L48: =+J48/$F$15 -> 56.973065
B49: ='Orcamento RU'!A2231 -> 1.3 | D49: ='Orcamento RU'!B2231 -> ПОЛЫ, ПОКРЫТИЯ И СТРОИТЕЛЬНЫЕ ЭЛЕМЕНТЫ | J49: ='Orcamento RU'!C2231 -> 38104.7 | L49: =+J49/$F$15 -> 97.007892
B50: ='Orcamento RU'!A2261 -> 1.4 | D50: ='Orcamento RU'!B2261 -> ОСВЕЩЕНИЕ - СВЕТОВЫЕ ТОЧКИ | J50: ='Orcamento RU'!C2261 -> 0 | L50: =+J50/$F$15 -> 0
B51: ='Orcamento RU'!A2283 -> 1.5 | D51: ='Orcamento RU'!B2283 -> ОБОРУДОВАНИЕ | J51: ='Orcamento RU'!C2283 -> 10548 | L51: =+J51/$F$15 -> 26.85336
B52: ='Orcamento RU'!A2295 -> II | D52: ='Orcamento RU'!B2295 -> ПОСАДКИ И ПОСЕВЫ | J52: ='Orcamento RU'!C2295 -> 73360.69 | L52: =+J52/$F$15 -> 186.76347
B53: ='Orcamento RU'!A2421 -> III | D53: ='Orcamento RU'!B2421 -> ПОЛИВ | J53: ='Orcamento RU'!C2421 -> 33665.94 | L53: =+J53/$F$15 -> 85.707587
B54: ='Orcamento RU'!A2497 -> IV | D54: ='Orcamento RU'!B2497 -> ОБСЛУЖИВАНИЕ ЗЕЛЕНЫХ ЗОН | J54: ='Orcamento RU'!C2497 -> 9600 | L54: =+J54/$F$15 -> 24.439919
B56: ИТОГО ЗА ЖИЛЬЕ | J56: =SUM(J25:J54) -> 2405735 | L56: =+J56/$F$15 -> 6124.58
...

Sheet Orcamento RU
A1: № | B1: ОПИСАНИЕ РАБОТ | C1: ЕД. ИЗМ. | D1: КОЛ-ВО | E1: ЦЕНА ЗА ЕДИНИЦУ | F1: ОБЩАЯ СТОИМОСТЬ | G1: My Unit Price | H1: My total Price | I1: My Savings | J1: FALSE
J2: FALSE
J3: FALSE
A4: 1 | B4: СТРОИТЕЛЬНАЯ ПЛОЩАДКА | C4: =F8 -> 173610.4 | E4: 85000 | J4: FALSE
J5: FALSE
A6: 1.1 | B6: СТРОИТЕЛЬНАЯ ПЛОЩАДКА И ДОПОЛНИТЕЛЬНЫЕ РАБОТЫ | J6: FALSE
J7: FALSE
A8: 1.1.1 | B8: Монтаж, строительство, обслуживание, демонтаж и снос строительной площадки, включая соответствующие установки, временные сети водоснабжения, канализации, электричества и средства телекоммуникаций, внутренние пути движения и все остальное необходимое в соответствии с Декретом-Законом № 18/08 от 29 января, удовлетворяющее предписаниям по безопасности, гигиене и охране труда, в соответствии с Декретом-Законом № 273/2003 от 29 октября и прочим действующим законодательством, разработка и внедрение плана предотвращения и управления отходами строительства и сноса (в понимании Д.З. № 46/2008 от 12 марта). | C8: vg | D8: 1 | E8: 173610.4 | F8: 173610.4 | J8: TRUE
J9: FALSE
A10: 2.1 | B10: КАМЕННАЯ КЛАДКА И ЛЁГКИЕ ОГРАЖДАЮЩИЕ КОНСТРУКЦИИ | C10: =SUM(F14:F40) -> 27737.99 | E10: 27000 | J10: FALSE
J11: FALSE
A12: 2.1.1 | B12: НАРУЖНАЯ КЛАДКА | J12: FALSE
J13: FALSE
A14: 2.1.1.1 | B14: Поставка и выполнение наружной стены с 1 слоем термического кирпича Preceram толщиной 25 см, включая кладочный раствор в пропорции 1:4, железобетонные перемычки над проемами, анкеры из нержавеющей стали для связи между кладкой и бетонной конструкцией и все подготовительные работы и аксессуары, необходимые для идеального завершения. (PE-A) (PE-B) (PE-C) (PE-D) (PE-E) (PE-P) (PE-F) | C14: m2 | D14: 155.42 | E14: 50.66 | F14: 7873.58 | J14: FALSE
J15: FALSE
A16: 2.1.1.2 | B16: Поставка и выполнение наружной стены с 1 слоем кладки из керамического кирпича размером 30x20x15 см, включая кладочный раствор в пропорции 1:4, железобетонные перемычки над проемами и все подготовительные работы и аксессуары, необходимые для идеального завершения. (PE-M) (PE-N) | C16: m2 | D16: 32.57 | E16: 32 | F16: 1042.24 | J16: FALSE
J17: FALSE
A18: 2.1.1.3 | B18: Поставка и выполнение наружной стены с 1 слоем кладки из керамического кирпича размером 30x20x11 см, включая кладочный раствор в пропорции 1:4, железобетонные перемычки над проемами, в промежутках воздушных камер предусмотреть желоб в стяжке с уклоном для отвода конденсационной воды к сливу с выходом, и все подготовительные работы и аксессуары, необходимые для идеального завершения. (PE-H) (PE-K) (PE-L) | C18: m2 | D18: 144.31 | E18: 28.06 | F18: 4049.34 | J18: FALSE
J19: FALSE
A20: 2.1.2 | B20: ВНУТРЕННЯЯ КЛАДКА | J20: FALSE
J21: FALSE
A22: 2.1.2.1 | B22: Поставка и выполнение внутренних стен с 1 слоем кладки из керамического кирпича размером 30x20x15 см, включая кладочный раствор в пропорции 1:4, железобетонные перемычки над проемами и все подготовительные работы и аксессуары, необходимые для идеального завершения. (PI-A) (PI-B) | C22: m2 | D22: 152.25 | E22: 32 | F22: 4872 | J22: FALSE
J23: FALSE
A24: 2.1.2.2 | B24: Поставка и выполнение внутренних стен с 1 слоем кладки из керамического кирпича размером 30x20x7 см, включая кладочный раствор в пропорции 1:4, железобетонные перемычки над проемами и все подготовительные работы и аксессуары, необходимые для идеального завершения. (PI-C) | C24: m2 | D24: 14.64 | E24: 25.22 | F24: 369.22 | J24: FALSE
J25: FALSE
A26: 2.1.2.3 | B26: Поставка и выполнение внутренних стен с 2 слоями кладки из керамического кирпича размером 30x20x11 см + воздушная камера 3 см + 30x20x11 см, включая кладочный раствор в пропорции 1:4, железобетонные перемычки над проемами и все подготовительные работы и аксессуары, необходимые для идеального завершения. (PI-D) (PI-E) | C26: m2 | D26: 48.01 | E26: 56.13 | F26: 2694.8 | J26: FALSE
J27: FALSE
A28: 2.1.3 | B28: ЛЕГКИЕ ВНУТРЕННИЕ ПЕРЕГОРОДКИ | J28: FALSE
J29: FALSE
A30: 2.1.3.1 | B30: Поставка и выполнение облицовки гипсокартонными плитами толщиной 12 мм на внутренних поверхностях наружных стен, система двойной обшивки, внутреннее заполнение минеральной ватой толщиной 9 см, включая профилированную конструкцию для поддержки плит со стойками 90 мм, систему крепления, обработку швов, шпатлевку и финишную подготовку под покраску или финишную отделку и все подготовительные работы и аксессуары, необходимые для идеального завершения. (PE-P) | C30: m2 | D30: 19.35 | E30: 54.18 | F30: 1048.38 | J30: FALSE
J31: FALSE
A32: 2.1.3.2 | B32: Поставка и выполнение облицовки стандартными гипсокартонными плитами толщиной 12 мм на внутренних поверхностях наружных стен, система двойной обшивки, внутреннее заполнение минеральной ватой толщиной 5 см, включая профилированную конструкцию для поддержки плит со стойками 48 мм, систему крепления, обработку швов, шпатлевку и финишную подготовку под покраску или финишную отделку и все подготовительные работы и аксессуары, необходимые для идеального завершения. (PE-C) (PE-D) (PI-G) | C32: m2 | D32: 37.64 | E32: 52.76 | F32: 1985.89 | J32: FALSE
J33: FALSE
A34: 2.1.3.3 | B34: Поставка и выполнение облицовки влагостойкими гипсокартонными плитами толщиной 12 мм на внутренних поверхностях наружных стен, система двойной обшивки, внутреннее заполнение минеральной ватой толщиной 5 см, включая профилированную конструкцию для поддержки плит со стойками 48 мм, систему крепления, обработку швов, шпатлевку и финишную подготовку под покраску или финишную отделку и все подготовительные работы и аксессуары, необходимые для идеального завершения. (PE-I) (PI-H) | C34: m2 | D34: 20.27 | E34: 62.72 | F34: 1271.33 | J34: FALSE
J35: FALSE
A36: 2.1.3.4 | B36: Поставка и выполнение облицовки влагостойкими гипсокартонными плитами толщиной 12 мм на внутренних поверхностях наружных стен, система двойной обшивки, внутреннее заполнение минеральной ватой толщиной 3 см, включая профилированную конструкцию для поддержки плит со стойками 30 мм, систему крепления, обработку швов, шпатлевку и финишную подготовку под покраску или финишную отделку и все подготовительные работы и аксессуары, необходимые для идеального завершения. (PE-J) | C36: m2 | D36: 10.99 | E36: 60.65 | F36: 666.54 | J36: FALSE
J37: FALSE
A38: 2.1.3.5 | B38: Поставка и монтаж легких перегородок с двойной обшивкой влагостойким гипсокартоном толщиной 12 мм с каждой стороны, внутренняя облицовка акустической изоляцией из минеральной ваты толщиной 5 см, включая профилированную конструкцию для поддержки плит со стойками 48 мм, систему крепления, обработку швов, шпатлевку и финишную подготовку под покраску и все подготовительные работы и аксессуары, необходимые для идеального завершения. (PI-F) | C38: m2 | D38: 17.94 | E38: 52.76 | F38: 946.51 | J38: FALSE
J39: FALSE
A40: 2.1.3.6 | B40: Поставка и монтаж легких перегородок с простой обшивкой влагостойким МДФ толщиной 19 мм, лакированным с каждой стороны, с матовым покрытием цвета RAL 9003, внутренняя облицовка акустической изоляцией из минеральной ваты толщиной 4 см, включая конструкцию из труб FACAR диаметром 4 см для поддержки плит, систему крепления и все подготовительные работы и аксессуары, необходимые для идеального завершения. (PI-I) (PR06) | C40: m2 | D40: 12.91 | E40: 71.12 | F40: 918.16 | J40: FALSE
...

Sheet Example Orcamento PT Viora Buil
A1: № M | B1: № V | C1: DESCRIÇÃO DOS TRABALHOS | D1: UN. MED. | E1: QUANT. | F1: PREÇO UNITÁRIO | G1: VALOR TOTAL | H1: Comentário
B4: 1 | C4: CANTEIRO DE OBRAS E TRABALHOS COMPLEMENTARES | D4: =G8 | G4: =SUM(G10:G46) -> 108116 | H4: =G4-('Orcamento RU'!C4+'Orcamento RU'!C2206) -> -70094.4
C6: CANTEIRO DE OBRAS
A8: 1.1.1 (1) | B8: 1.1 | C8: Montagem, construção, manutenção, desmontagem e demolição do canteiro de obras, incluindo as respectivas instalações, redes provisórias de água, esgoto, eletricidade e meios de telecomunicações, vias internas de circulação e tudo mais necessário de acordo com o Decreto-Lei nº 18/08 de 29 de janeiro, atendendo às prescrições de segurança, higiene e saúde no trabalho, de acordo com o Decreto-Lei nº 273/2003 de 29 de outubro e demais legislação em vigor, elaboração e implementação do plano de prevenção e gestão de resíduos de construção e demolição (nos termos do D.L. nº 46/2008 de 12 de março).
A10: 1.1.1 (1) | B10: 1.1.1 | C10: Fornecimento e instalação, manutenção e desmontagem de vedação em torno do terreno com painéis opacos de chapa de aço galvanizado perfilada com espessura de 0,6 mm, com nervuras de altura entre 40 e 50 mm, colocadas a uma distância entre 250 e 270 mm, e perfis em S de chapa de aço galvanizado dobrada de dimensão 102x33x1,5 mm, com acabamento sendzimir, comprimento 2,8 m, fixados no solo por meio de cubos de concreto C20/25 XC0 Cl0.40 Dmax 25mm S2 de dimensão 102x33x1,5 cm, a cada 2,0 m, incluindo todos os trabalhos e materiais relacionados. | D10: ml | E10: 260 | F10: 100 | G10: =F10*E10 -> 26000 | H10: Pode construir a cerca de imediato, economizando 268000
A12: 1.1.1 (1) | B12: 1.1.2 | C12: Fornecimento e montagem, manutenção e desmontagem de portão deslizante para acesso de veículos em aço galvanizado de duas folhas com dimensões aproximadas de 4,0x2,0m com trava para cadeado e ferragens para fixação ao piso, instalado na vedação temporária do terreno, fixado por meio de postes do mesmo material, ancorados no solo por meio de cubos de concreto C20/25 XC0 Cl0.40 Dmáx 25mm S2, incluindo todos os trabalhos e materiais relacionados. | D12: vg | E12: 1 | F12: 800 | G12: =F12*E12 -> 800
A14: 1.1.1 (1) | B14: 1.1.3 | C14: Fornecimento e instalação de placa informativa, divulgando a construção, incluindo todos os trabalhos e materiais relacionados. | D14: vg | E14: 1 | F14: 120 | G14: =F14*E14 -> 120
A16: 1.1.1 (1) | B16: 1.1.4 | C16: Fornecimento e execução de redes primárias de eletricidade, água e esgoto, incluindo o consumo mensal durante todo o período de execução da obra até a recepção provisória, incluindo trabalhos e materiais relacionados. | D16: meses | E16: 18 | F16: 200 | G16: =F16*E16 -> 3600 | H16: Este ponto será resolvido de acordo com a situação
A18: 1.1.1 (1) | B18: 1.1.5 | C18: Fornecimento e montagem de módulo de escritório de dimensão 6,0x3,0 m para reuniões de obra, instalado sobre base nivelada de brita, com banheiro e ar condicionado, incluindo aterramento e todos os trabalhos e materiais relacionados. | D18: vg | E18: 1 | F18: 0 | G18: =F18*E18 -> 0 | H18: A pedido do cliente, para sua conveniência. Preço 12,000 euros
A20: 1.1.1 (1) | B20: 1.1.6 | C20: Fornecimento e montagem de módulo de ferramentaria geral de dimensão 3,0x2,40 m tipo contêiner marítimo, instalado sobre base nivelada de brita, incluindo todos os trabalhos e materiais relacionados. | D20: vg | E20: 1 | F20: 5200 | G20: =F20*E20 -> 5200
A22: 1.1.1 (1) | B22: 1.1.7 | C22: Fornecimento e instalação de bloco sanitário portátil em polietileno de dimensão 1,20x1,20x2,35m de cor cinza ou outra, sem ligações, com sanitário químico anaeróbico com sistema de descarga por pedal, espelho, porta com fechadura e teto translúcido para passagem de luz externa, incluindo limpeza semanal e todos os trabalhos e materiais relacionados. | D22: meses | E22: 18 | F22: 147 | G22: =F22*E22 -> 2646
A24: 1.1.1 (1) | B24: 1.8 | C24: Fornecimento e execução de implantação topográfica através de técnico especializado dos níveis de implantação da construção, incluindo piscina e limites, bem como todos os trabalhos e materiais relacionados. | D24: vg | E24: 1 | F24: 1530 | G24: =F24*E24 -> 1530
A26: 1.1.1 (1) | B26: 1.9 | C26: Fornecimento e montagem de andaimes de tubos padrão, tipo multidirecional, até 9 m de altura, constituídos por estrutura tubular de aço laminado a quente galvanizado de diâmetro 48,3 mm e espessura 3,2 mm, sem duplicação de elementos verticais, compostos por plataformas de trabalho de 60 cm de largura, colocadas a cada 2 m de altura, escada interior com alçapão, guarda-costas com dois corrimãos e rodapé, e guarda-frente com um corrimão, para execução de fachada(s) com elementos estruturais (terraços cobertos e descobertos, cornijas e outros, etc.) dispostos em mais de 50% do seu perímetro e que se projetam mais de 30 cm do plano da fachada. Nota (1): os andaimes devem estar em total conformidade com a legislação em vigor, nomeadamente EN 12811 e EN 12810. | D26: meses | E26: 18 | F26: 500 | G26: =F26*E26 -> 9000 | H26: Aluguel de andaimes
A28: 1.1.1 (1) | B28: 1.10 | C28: Fornecimento, execução e implementação/adaptação do plano de segurança e saúde (PSS) na fase de construção, incluindo todos os trabalhos e materiais relacionados. | D28: meses | E28: 18 | F28: 390 | G28: =F28*E28 -> 7020 | H28: O seguro do objeto pode variar entre 300-500 euros. Foi fornecida a informação mais recente
A30: 1.1.1 (1) | B30: 1.11 | C30: Fornecimento, execução e implementação/adaptação do plano de gestão de resíduos (PGR), sua classificação (LER), triagem e separação nas suas componentes recicláveis e respectiva eliminação ou transporte para zonas de reciclagem e para operadores autorizados e licenciados, de acordo com a legislação em vigor. | D30: meses | E30: 18 | F30: 300 | G30: =F30*E30 -> 5400 | H30: Este ponto será resolvido de acordo com a situação
A32: 1.1.1 (1) | B32: 1.12 | C32: Elaboração e entrega ao dono da obra da compilação técnica da obra, que inclui elementos úteis a ter em conta na sua utilização futura, bem como na realização de trabalhos posteriores à sua conclusão para preservar a segurança e saúde dos que os executam, de acordo com o disposto no artigo 16º do Decreto-Lei nº 273/2003 de 29 de outubro, considerando os desenhos finais de todas as especialidades em papel e suporte digital, todos os estudos, projetos, documentação anexa e relacionada. | D32: vg | E32: 1 | F32: 0 | G32: =F32*E32 -> 0 | H32: Incluído no custo do próprio projeto
A34: 1.1.1 (1) | B34: 1.13 | C34: Fornecimento e coordenação de recursos humanos e materiais necessários para a limpeza e manutenção do canteiro de obras, incluindo a instalação de todos os equipamentos de segurança, como guarda-corpos e linhas de vida, etc., tudo de acordo com a legislação em vigor. | D34: meses | E34: 18 | F34: 150 | G34: =F34*E34 -> 2700
A36: 1.1.1 (1) | B36: 1.14 | C36: Fornecimento de pessoal especializado, nomeadamente diretor de projeto (engenheiro civil), encarregado geral, preparador de obra. | D36: meses | E36: 18 | F36: 450 | G36: =F36*E36 -> 8100
A38: 1.1.1 (1) | B38: 1.15 | C38: Fornecimento e instalação de equipamentos e materiais de segurança, colocados em locais visíveis, incluindo todos os trabalhos e materiais relacionados. | D38: vg | E38: 1 | F38: 1500 | G38: =F38*E38 -> 1500
C40: GUINDASTE
B42: 1.16 | C42: Fornecimento e execução de escavação em qualquer tipo de solo para a base do guindaste, incluindo depósito de terra em armazenamento para aterros, compactação e nivelamento da base da plataforma de trabalho, bem como todos os trabalhos e materiais relacionados. | D42: vg | E42: 1 | F42: 0 | G42: =F42*E42 -> 0 | H42: Incluído no custo dos trabalhos de terraplenagem
B44: 1.17 | C44: Fornecimento e execução de elementos estruturais de concreto tipo C25/30 XC2(P) Dmáx 20mm S3, fabricados, transportados e colocados em obra de acordo com NP EN 206-1 e NP ENV 13670-1 para a base de instalação do guindaste, incluindo execução de fôrmas e armaduras em aço tipo A500NR SD e todos os trabalhos necessários para um acabamento de qualidade, tudo de acordo com o projeto de estabilidade, incluindo todos os trabalhos e materiais relacionados. Nota (1): deve-se considerar a desmontagem da fundação do guindaste. | D44: vg | E44: 1 | F44: 8000 | G44: =F44*E44 -> 8000
B46: 1.18 | C46: Fornecimento e operação de guindaste de torre com lança extensível de 50 m com características adequadas à obra, incluindo controle por rádio e por cabo, balde-trenó de 300 litros e palete para 2000 kg. | D46: vg | E46: 1 | F46: =SUM(G48:G52) -> 26500 | G46: =F46*E46 -> 26500
B48: 1.18.1 | C48: Montagem do guindaste. | D48: vg | E48: 1 | F48: 1700 | G48: =F48*E48 -> 1700
B49: 1.18.2 | C49: Operação do guindaste. | D49: meses | E49: 14 | F49: 1500 | G49: =F49*E49 -> 21000
B50: 1.18.3 | C50: Desmontagem do guindaste. | D50: vg | E50: 1 | F50: 1700 | G50: =F50*E50 -> 1700
B51: 1.18.4 | C51: Entrega do guindaste. | D51: peças | E51: 1 | F51: 1050 | G51: =F51*E51 -> 1050
B52: 1.18.5 | C52: Retirada do guindaste. | D52: peças | E52: 1 | F52: 1050 | G52: =F52*E52 -> 1050
B55: 2 | C55: MOVIMENTO DE TERRAS | G55: =SUM(G59:G71) -> 34482.88 | H55: =G55-('Orcamento RU'!C749+'Orcamento RU'!C2217) -> -39311.59
C57: MOVIMENTO DE TERRAS
A59: 1,1 (2) | B59: 2.1 | C59: Limpeza geral do terreno, incluindo todos os tipos de trabalhos de limpeza, remoção, desmatamento e corte de espécies arbóreas, existentes e necessárias para a execução geral dos projetos. | D59: un | E59: 1 | F59: 4000 | G59: =F59*E59 -> 4000
A61: 1,2 (2) | B61: 2.2 | C61: Execução de escavação geral para implantação da estrutura da habitação, piscina e muros em solo de qualquer tipo (incluindo rocha), para atingir as cotas iniciais de fundação, bem como execução de trabalhos de escoramento, escoras, drenagem, incluindo todos os trabalhos relacionados. | D61: m³ | E61: 2234.27 | F61: 4 | G61: =F61*E61 -> 8937.08
A63: 1,3 (2) | B63: 2.3 | C63: Execução de aterros na zona da habitação, piscina e terraços exteriores com materiais provenientes da escavação, incluindo espalhamento e compactação adequada, executada por meios mecânicos, em camadas de espessura máxima de 0,30 m, com utilização de água na quantidade necessária para a correta compactação, para atingir os níveis de projeto, incluindo todos os trabalhos relacionados. | D63: m³ | E63: 482.44 | F63: 5 | G63: =F63*E63 -> 2412.2
A65: 1.4.1 (2) | B65: 2.4 | C65: Transporte, carga e descarga de excedentes de solo da zona da habitação para vazadouro, incluindo 20% de empolamento, bem como todos os trabalhos relacionados. | D65: m³ | E65: 2102.2 | F65: 8 | G65: =F65*E65 -> 16817.6
A67: 1.2.1.1 (3) | B67: 2.5 | C67: Escavação de solo de qualquer natureza até as cotas de projeto, incluindo transporte para zonas de aterro, os restantes devem ser transportados para depósito autorizado, incluindo transporte, compensações, bem como todos os meios, trabalhos, materiais necessários. | D67: m3 | E67: 68 | F67: 3 | G67: =F67*E67 -> 204
A69: 1.2.2.1 (3) | B69: 2.6 | C69: Aterro em camadas até as cotas de projeto com solo selecionado proveniente das escavações ou de zonas de empréstimo fora da área de intervenção, incluindo transporte, todos os meios, trabalhos, materiais necessários. | D69: m3 | E69: 386 | F69: 3 | G69: =F69*E69 -> 1158
A71: 1.2.3.1 (3) | B71: 2.7 | C71: Fornecimento, carga, transporte, descarga, espalhamento de solo de empréstimo, bem como todos os meios, trabalhos, materiais necessários. | D71: m3 | E71: 318 | F71: 3 | G71: =F71*E71 -> 954
B73: 3 | C73: ESTRUTURA DE CONCRETO ARMADO | G73: =SUM(G79:G269) -> 567388.82 | H73: =G73-'Orcamento RU'!C761 -> 8996.574
C75: Concreto
A77: 2.1.1 (2) | B77: 3.1 | C77: Fornecimento e colocação de concreto magro C12/15, com classe de exposição X0, Cl 1.0, Dmax 25mm, S3, com espessura de 5 cm sob elementos de fundação, incluindo nivelamento prévio e compactação do fundo das escavações, colocado na forma geométrica dos seguintes elementos:
...

Sheet Orcamento PT
A4: Item | B4: Descrição | D4: UN | E4: Quantidade | F4: PREÇO
F5: Unitário | G5: T O T A L
D8: Units | E8: Quantity | F8: Unit Price | G8: Total | H8: My Unit Price | I8: My total Price | J8: My Savings
B10: EXECUÇÃO DE MORADIA - URB. DAS GAIVOTAS MATA PORCAS, PRAIA DA LUZ
A12: 1 | B12: ESTALEIRO
A14: 1.1 | B14: ESTALEIRO E TRABALHOS COMPLEMENTARES
A16: 1.1.1 | B16: Montagem, construção, manutenção, desmontagem e demolição de estaleiro, incluindo as correspondentes instalações, redes provisórias de água, esgoto, electricidade e meios de telecomunicações, vias internas de circulação e tudo o mais necessário de acordo com o Dec-Lei n.º 18/08, de 29 de Janeiro, satisfazendo as prescrições relativas à Segurança, Higiene e Saúde no trabalho, em conformidade com o Dec-Lei n.º 273/2003 de 29 de Outubro e demais legislação em vigor, Desenvolvimento e Implementação do Plano de Prevenção e Gestão de Resíduos de Construção e Demolição (na acepção do D.L. Nº46/2008 de 12 de Março). | D16: vg | E16: 1 | F16: 173610.4 | G16: 173610.4
A18: 1.1 | B18: ESTALEIRO E TRABALHOS COMPLEMENTARES | G18: 173610.4
A20: 1 | B20: ESTALEIRO | G20: 173610.4 | H20: =G20 -> 173610.4
A23: 2 | B23: ARQUITECTURA
A25: 2.1 | B25: ALVENARIAS E PARAMENTOS LEVES
A27: 2.1.1 | B27: ALVENARIAS EXTERIORES
A29: 2.1.1.1 | B29: Fornecimento e execução de parede exterior com 1 pano de tijolo térmico Preceram com 25cm de espessura, incluindo argamassa de assentamento ao traço 1:4, vergas de betão armado sobre vãos, gatos de travamento em aço inox entre alvenarias e estrutura de betão e todos os trabalhos preparatórios e acessórios necessários a um perfeito acabamento. (PE-A) (PE-B) (PE-C) (PE-D) (PE-E) (PE-P) (PE-F) | D29: m2 | E29: 155.42 | F29: 50.66 | G29: 7873.58
A31: 2.1.1.2 | B31: Fornecimento e execução de parede exterior com 1 pano em alvenaria de tijolo cerâmico com 30x20x15cm, incluindo argamassa de assentamento ao traço 1:4, vergas de betão armado sobre vãos e todos os trabalhos preparatórios e acessórios necessários a um perfeito acabamento. (PE-M) (PE-N) | D31: m2 | E31: 32.57 | F31: 32 | G31: 1042.24
A33: 2.1.1.3 | B33: Fornecimento e execução de parede exterior com 1 pano em alvenaria de tijolo cerâmico com 30x20x11cm, incluindo argamassa de assentamento ao traço 1:4, vergas de betão armado sobre vãos, nos intervalos de caixas de ar prever canaleta em betonilha com pendente para escoamento de águas de condensação para ralo com saída, e todos os trabalhos preparatórios e acessórios necessários a um perfeito acabamento. (PE-H) (PE-K) (PE-L) | D33: m2 | E33: 144.31 | F33: 28.06
A35: 2.1.2 | B35: ALVENARIAS INTERIORES
A37: 2.1.2.1 | B37: Fornecimento e execução de paredes interiores com 1 pano em alvenaria de tijolo cerâmico com 30x20x15cm, incluindo argamassa de assentamento ao traço 1:4, vergas de betão armado sobre vãos e todos os trabalhos preparatórios e acessórios necessários a um perfeito acabamento. (PI-A) (PI-B) | D37: m2 | E37: 152.25 | F37: 32 | G37: 4872
A39: 2.1.2.2 | B39: Fornecimento e execução de paredes interiores com 1 pano em alvenaria de tijolo cerâmico com 30x20x7cm, incluindo argamassa de assentamento ao traço 1:4, vergas de betão armado sobre vãos e todos os trabalhos preparatórios e acessórios necessários a um perfeito acabamento. (PI-C) | D39: m2 | E39: 14.64 | F39: 25.22 | G39: 369.22
A41: 2.1.2.3 | B41: Fornecimento e execução de paredes interiores com 2 panos em alvenaria de tijolo cerâmico com 30x20x11cm + caixa de ar 3cm + 30x20x11cm, incluindo argamassa de assentamento ao traço 1:4, vergas de betão armado sobre vãos e todos os trabalhos preparatórios e acessórios necessários a um perfeito acabamento. (PI-D) (PI-E) | D41: m2 | E41: 48.01 | F41: 56.13 | G41: 2694.8
A43: 2.1.3 | B43: PARAMENTOS LEVES INTERIORES
A45: 2.1.3.1 | B45: Fornecimento e execução de revestimento em placas de gesso cartonado de 12mm, em faces interiores das paredes exteriores, sistema de dupla placagem, preenchimento interior com lã de rocha com 9cm de espessura, incluindo estrutura perfilada para suporte das placas com montantes de 90mm, sistema de fixação, tratamento de juntas, barramento e preparação final para receber pintura ou revestimento final e todos os trabalhos preparatórios e acessórios necessários a um perfeito acabamento. (PE-P) | D45: m2 | E45: 19.35 | F45: 54.18 | G45: 1048.38
A47: 2.1.3.2 | B47: Fornecimento e execução de revestimento em placas de gesso cartonado standard de 12mm, em faces interiores das paredes exteriores, sistema de dupla placagem, preenchimento interior com lã de rocha com 5cm de espessura, incluindo estrutura perfilada para suporte das placas com montantes de 48mm, sistema de fixação, tratamento de juntas, barramento e preparação final para receber pintura ou revestimento final e todos os trabalhos preparatórios e acessórios necessários a um perfeito acabamento. (PE-C) (PE-D) (PI-G) | D47: m2 | E47: 37.64 | F47: 52.76 | G47: 1985.89
A49: 2.1.3.3 | B49: Fornecimento e execução de revestimento em placas de gesso cartonado hidrófugo de 12mm, em faces interiores das paredes exteriores, sistema de dupla placagem, preenchimento interior com lã de rocha com 5cm de espessura, incluindo estrutura perfilada para suporte das placas com montantes de 48mm, sistema de fixação, tratamento de juntas, barramento e preparação final para receber pintura ou revestimento final e todos os trabalhos preparatórios e acessórios necessários a um perfeito acabamento. (PE-I) (PI-H) | D49: m2 | E49: 20.27 | F49: 62.72 | G49: 1271.33
A51: 2.1.3.4 | B51: Fornecimento e execução de revestimento em placas de gesso cartonado hidrófugo de 12mm, em faces interiores das paredes exteriores, sistema de dupla placagem, preenchimento interior com lã de rocha com 3cm de espessura, incluindo estrutura perfilada para suporte das placas com montantes de 30mm, sistema de fixação, tratamento de juntas, barramento e preparação final para receber pintura ou revestimento final e todos os trabalhos preparatórios e acessórios necessários a um perfeito acabamento. (PE-J) | D51: m2 | E51: 10.99 | F51: 60.65 | G51: 666.54
A53: 2.1.3.5 | B53: Fornecimento e montagem de paramentos leves em dupla placagem de gesso cartonado hidrófugo de 12mm por face, revestidas interiormente com isolamento acustico de lã de rocha de 5cm, incluindo estrutura perfilada para suporte das placas com montantes de 48mm, sistema de fixação, tratamento de juntas, barramento e preparação final para receber pintura e todos os trabalhos preparatórios e acessórios necessários a um perfeito acabamento. (PI-F) | D53: m2 | E53: 17.94 | F53: 52.76 | G53: 946.51
A55: 2.1.3.6 | B55: Fornecimento e montagem de paramentos leves em placagem simples de MDF hidrófugo 19mm lacado por face, com acabamento mate à cor RAL 9003, revestidas interiormente com isolamento acustico de lã de rocha de 4cm, incluindo estrutura em tubo FACAR de 4cm para suporte das placas, sistema de fixação e todos os trabalhos preparatórios e acessórios necessários a um perfeito acabamento. (PI-I) (PR06) | D55: m2 | E55: 12.91 | F55: 71.12 | G55: 918.16
A57: 2.1 | B57: ALVENARIAS E PARAMENTOS LEVES | G57: 27737.99 | H57: =G57 -> 27737.99
A60: 2.2 | B60: SOLEIRAS EM BETÃO
A62: 2.2.1 | B62: SOLEIRAS EM BETÃO
A64: 2.2.1.1 | B64: Fornecimento e execução de soleiras em betão com barramento, conforme detalhe PORM10, sobre-elevada 1cm com apoios de borracha ao critério do executante, incluindo cortes, remates e todos os trabalhos preparatórios e acessórios necessários a um perfeito acabamento.
A66: 2.2.1.1.1 | B66: Soleira VE 01.1 - Dimensão de 1.10m. | D66: un | E66: 1 | F66: 45.48 | G66: 45.48
A68: 2.2.1.1.2 | B68: Soleira VE 01.2 - Dimensão de 4.68m. | D68: un | E68: 1 | F68: 193.49 | G68: 193.49
A70: 2.2.1.1.3 | B70: Soleira VE 01.3 - Dimensão de 4.61m. | D70: un | E70: 1 | F70: 190.6 | G70: 190.6
A72: 2.2.1.1.4 | B72: Soleira VE 01.4 - Dimensão de 3.04m. | D72: un | E72: 1 | F72: 125.69 | G72: 125.69
A74: 2.2.1.2 | B74: Fornecimento e execução de soleiras estreitas entre vãos do piso 1, em peças de betão com barramento, conforme detalhe PORM10, sobre-elevada 1cm com apoios de borracha ao critério do executante, incluindo cortes, remates e todos os trabalhos preparatórios e acessórios necessários a um perfeito acabamento.
A76: 2.2.1.2.1 | B76: Soleira A - Dimensão de 400x70mm. | D76: un | E76: 1 | F76: 14.6 | G76: 14.6
A78: 2.2.1.2.2 | B78: Soleira B - Dimensão de 3960x70mm. | D78: un | E78: 1 | F78: 144.54 | G78: 144.54
A80: 2.2.1.2.3 | B80: Soleira C - Dimensão de 5300x70mm. | D80: un | E80: 1 | F80: 193.45 | G80: 193.45
A82: 2.2.1.2.4 | B82: Soleira D - Dimensão de 1390x70mm. | D82: un | E82: 1 | F82: 507.36 | G82: 507.36
A84: 2.2.1.2.5 | B84: Soleira E - Dimensão de 1040x70mm. | D84: un | E84: 1 | F84: 37.96 | G84: 37.96
...

Sheet Orcamento ENG
A4: Item | B4: Description | D4: UN | E4: Quantidade | F4: PREÇO
F5: Unitário | G5: T O T A L
D8: Units | E8: Quantity | F8: Unit Price | G8: Total | H8: My Unit Price | I8: My total Price | J8: My Savings
B10: HOUSING EXECUTION - URB. DAS GAIVOTAS MATA PORCAS, PRAIA DA LUZ
A12: 1 | B12: Site Setup
A14: 1.1 | B14: Site set up AND COMPLEMENTARY WORKS
A16: 1.1.1 | B16: Assembly, construction, maintenance, disassembly and demolition of a construction site, including the corresponding installations, temporary water, sewage, electricity and telecommunications networks, internal circulation routes and everything else necessary in accordance with Decree-Law no. October 29th and other legislation in force, Development and Implementation of the Construction and Demolition Waste Prevention and Management Plan (within the meaning of D.L. No. 46/2008 of March 12th). | D16: vg | E16: 1 | F16: 173610.4 | G16: 173610.4
A18: 1.1 | B18: Site Setup AND COMPLEMENTARY WORKS | G18: 173610.4
A20: 1 | B20: Site Setup | G20: 173610.4 | H20: =G20 -> 173610.4
A23: 2 | B23: ARCHITECTURE
A25: 2.1 | B25: MASONRY AND LIGHTWEIGHT PAMENTS
A27: 2.1.1 | B27: EXTERIOR MASONRY
A29: 2.1.1.1 | B29: Supply and execution of an external wall with 1 sheet of Preceram thermal brick 25cm thick, including laying mortar in a 1:4 ratio, reinforced concrete lintels over gaps, stainless steel locking cats between masonry and concrete structure and all preparatory work and accessories necessary for a perfect finish. (PE-A) (PE-B) (PE-C) (PE-D) (PE-E) (PE-P) (PE-F) | D29: m2 | E29: 155.42 | F29: 50.66 | G29: 7873.58
A31: 2.1.1.2 | B31: Supply and execution of an exterior wall with 1 panel in ceramic brick masonry measuring 30x20x15cm, including laying mortar at 1:4, reinforced concrete lintels over gaps and all preparatory work and accessories necessary for a perfect finish. (PE-M) (PE-N) | D31: m2 | E31: 32.57 | F31: 32 | G31: 1042.24
A33: 2.1.1.3 | B33: Supply and execution of an external wall with 1 panel in ceramic brick masonry measuring 30x20x11cm, including laying mortar in a 1:4 line, reinforced concrete lintels over gaps, in the intervals between air boxes provide a channel in the subfloor with a slope for the drainage of condensation water to a drain with an exit, and all the preparatory work and accessories necessary for a perfect finish. (PE-H) (PE-K) (PE-L) | D33: m2 | E33: 144.31 | F33: 28.06 | G33: 4049.34
A35: 2.1.2 | B35: INTERIOR MASONRY
A37: 2.1.2.1 | B37: Supply and execution of interior walls with 1 panel in ceramic brick masonry measuring 30x20x15cm, including laying mortar at 1:4, reinforced concrete lintels over gaps and all preparatory work and accessories necessary for a perfect finish. (PI-A) (PI-B) | D37: m2 | E37: 152.25 | F37: 32 | G37: 4872
A39: 2.1.2.2 | B39: Supply and execution of interior walls with 1 panel in ceramic brick masonry measuring 30x20x7cm, including laying mortar at 1:4, reinforced concrete lintels over gaps and all preparatory work and accessories necessary for a perfect finish. (PI-C) | D39: m2 | E39: 14.64 | F39: 25.22 | G39: 369.22
A41: 2.1.2.3 | B41: Supply and execution of interior walls with 2 panels in ceramic brick masonry measuring 30x20x11cm + air box 3cm + 30x20x11cm, including laying mortar at 1:4, reinforced concrete lintels over gaps and all preparatory work and accessories necessary for a perfect finish. (PI-D) (PI-E) | D41: m2 | E41: 48.01 | F41: 56.13 | G41: 2694.8
A43: 2.1.3 | B43: LIGHT INTERIOR APPLIANCES
A45: 2.1.3.1 | B45: Supply and execution of cladding in 12mm plasterboard sheets, on the interior sides of the exterior walls, double plating system, interior filling with 9cm thick rock wool, including profiled structure to support the boards with 90mm uprights, fixing system, joint treatment, smoothing and final preparation to receive painting or final coating and all preparatory work and accessories necessary for a perfect finish. (PE-P) | D45: m2 | E45: 19.35 | F45: 54.18 | G45: 1048.38
A47: 2.1.3.2 | B47: Supply and execution of cladding in standard 12mm plasterboard sheets, on the interior sides of exterior walls, double plating system, interior filling with 5cm thick rock wool, including profiled structure to support the boards with 48mm uprights, fixing system, joint treatment, smoothing and final preparation to receive painting or final coating and all preparatory work and accessories necessary for a perfect finish. (PE-C) (PE-D) (PI-G) | D47: m2 | E47: 37.64 | F47: 52.76 | G47: 1985.89
A49: 2.1.3.3 | B49: Supply and execution of cladding in 12mm water-repellent plasterboard sheets, on the interior sides of exterior walls, double plating system, interior filling with 5cm thick rock wool, including profiled structure to support the boards with 48mm uprights, fixing system, joint treatment, smoothing and final preparation to receive painting or final coating and all preparatory work and accessories necessary for a perfect finish. (PE-I) (PI-H) | D49: m2 | E49: 20.27 | F49: 62.72 | G49: 1271.33
A51: 2.1.3.4 | B51: Supply and execution of cladding in 12mm water-repellent plasterboard sheets, on the interior sides of exterior walls, double plating system, interior filling with 3cm thick rock wool, including profiled structure to support the boards with 30mm uprights, fixing system, joint treatment, smoothing and final preparation to receive painting or final coating and all preparatory work and accessories necessary for a perfect finish. (PE-J) | D51: m2 | E51: 10.99 | F51: 60.65 | G51: 666.54
A53: 2.1.3.5 | B53: Supply and assembly of lightweight walls in double 12mm water-repellent plasterboard panels per side, internally coated with 5cm rock wool acoustic insulation, including profiled structure to support the plates with 48mm uprights, fixing system, joint treatment, sealing and final preparation to receive painting and all preparatory work and accessories necessary for a perfect finish. (PI-F) | D53: m2 | E53: 17.94 | F53: 52.76 | G53: 946.51
A55: 2.1.3.6 | B55: Supply and assembly of lightweight walls in simple 19mm water-repellent MDF board, lacquered on each side, with a matte finish in the color RAL 9003, covered internally with 4cm rock wool acoustic insulation, including a 4cm FACAR tube structure to support the plates, fixing system and all preparatory work and accessories necessary for a perfect finish. (PI-I) (PR06) | D55: m2 | E55: 12.91 | F55: 71.12 | G55: 918.16
A57: 2.1 | B57: MASONRY AND LIGHTWEIGHT PAMENTS | G57: 27737.99 | H57: =G57 -> 27737.99
A60: 2.2 | B60: CONCRETE SILLS
A62: 2.2.1 | B62: CONCRETE SILLS
A64: 2.2.1.1 | B64: Supply and execution of concrete sills with bars, according to detail PORM10, raised 1cm with rubber supports at the discretion of the executor, including cuts, finishes and all preparatory work and accessories necessary for a perfect finish.
A66: 2.2.1.1.1 | B66: Threshold VE 01.1 - Dimension 1.10m. | D66: un | E66: 1 | F66: 45.48 | G66: 45.48
A68: 2.2.1.1.2 | B68: Threshold VE 01.2 - Dimension 4.68m. | D68: un | E68: 1 | F68: 193.49 | G68: 193.49
A70: 2.2.1.1.3 | B70: Threshold VE 01.3 - Dimension 4.61m. | D70: un | E70: 1 | F70: 190.6 | G70: 190.6
A72: 2.2.1.1.4 | B72: Threshold VE 01.4 - Dimension 3.04m. | D72: un | E72: 1 | F72: 125.69 | G72: 125.69
A74: 2.2.1.2 | B74: Supply and execution of narrow sills between gaps on the 1st floor, in concrete parts with bars, according to detail PORM10, raised 1cm with rubber supports at the discretion of the contractor, including cuts, finishes and all preparatory work and accessories necessary for a perfect finish.
A76: 2.2.1.2.1 | B76: Threshold A - Dimensions 400x70mm. | D76: un | E76: 1 | F76: 14.6 | G76: 14.6
A78: 2.2.1.2.2 | B78: Threshold B - Dimensions 3960x70mm. | D78: un | E78: 1 | F78: 144.54 | G78: 144.54
A80: 2.2.1.2.3 | B80: Threshold C - Dimensions 5300x70mm. | D80: un | E80: 1 | F80: 193.45 | G80: 193.45
A82: 2.2.1.2.4 | B82: Threshold D - Dimensions 1390x70mm. | D82: un | E82: 1 | F82: 507.36 | G82: 507.36
A84: 2.2.1.2.5 | B84: Threshold E - Dimensions 1040x70mm. | D84: un | E84: 1 | F84: 37.96 | G84: 37.96
...

Sheet Resumo Viora Build
A1: 25-
B9: Клиент | F9: Matthew Renier
B11: Местоположение | F11: Das Gaivotas, Mata Porcas, Praia da Luz
B13: Описание работ
B15: Общая площадь застройки (м²) | F15: 392.8
B17: Прочее (цоколь, бассейн, пристройки, стены): | F17: 782.27
B19: Бассейн (м²) | F19: 100
B21: Дата | F21: 45812
B23: АРТ º | D23: ОПИСАНИЕ РАБОТ | J23: ИТОГО ПО РАЗДЕЛУ | L23: СТОИМОСТЬ (м2)
B25: ='Orcamento RU Viora Build'!C4 -> 1 | D25: ='Orcamento RU Viora Build'!D4 -> СТРОИТЕЛЬНАЯ ПЛОЩАДКА И ДОПОЛНИТЕЛЬНЫЕ РАБОТЫ | J25: ='Orcamento RU Viora Build'!H4 -> 2015 | L25: =+J25/$F$15 -> 5.1298371
B26: ='Orcamento RU Viora Build'!C56 -> 2 | D26: ='Orcamento RU Viora Build'!D56 -> ЗЕМЛЯНЫЕ РАБОТЫ | J26: ='Orcamento RU Viora Build'!H56 -> 69140.305 | L26: =+J26/$F$15 -> 176.01911
B27: ='Orcamento RU Viora Build'!C74 -> 3 | D27: ='Orcamento RU Viora Build'!D74 -> ЖЕЛЕЗОБЕТОННАЯ КОНСТРУКЦИЯ | J27: ='Orcamento RU Viora Build'!H74 -> 468347.35 | L27: =+J27/$F$15 -> 1192.3303
B28: ='Orcamento RU Viora Build'!C389 -> 4 | D28: ='Orcamento RU Viora Build'!D389 -> ГИДРОИЗОЛЯЦИЯ И ТЕПЛОИЗОЛЯЦИЯ | J28: ='Orcamento RU Viora Build'!H389 -> 52593.507 | L28: =+J28/$F$15 -> 133.89386
B29: ='Orcamento RU Viora Build'!C511 -> 5 | D29: ='Orcamento RU Viora Build'!D511 -> КАМЕННАЯ КЛАДКА И ОГРАЖДАЮЩИЕ КОНСТРУКЦИИ | J29: ='Orcamento RU Viora Build'!H511 -> 27664.108 | L29: =+J29/$F$15 -> 70.427973
B30: ='Orcamento RU Viora Build'!C669 -> 6 | D30: ='Orcamento RU Viora Build'!D669 -> КРОВЛЯ | J30: ='Orcamento RU Viora Build'!H669 -> 56228.093 | L30: =+J30/$F$15 -> 143.14688
B31: ='Orcamento RU Viora Build'!C701 -> 7 | D31: ='Orcamento RU Viora Build'!D701 -> ОТДЕЛКА ПОТОЛКОВ | J31: ='Orcamento RU Viora Build'!H701 -> 14727.368 | L31: =+J31/$F$15 -> 37.4933
B32: ='Orcamento RU Viora Build'!C769 -> 8 | D32: ='Orcamento RU Viora Build'!D769 -> ОТДЕЛКА СТЕН | J32: ='Orcamento RU Viora Build'!H769 -> 127239.06 | L32: =+J32/$F$15 -> 323.92835
B33: ='Orcamento RU Viora Build'!C857 -> 9 | D33: ='Orcamento RU Viora Build'!D857 -> ОТДЕЛКА ПОЛОВ И ПЛИНТУСОВ | J33: ='Orcamento RU Viora Build'!H857 -> 101274.85 | L33: =+J33/$F$15 -> 257.82803
B34: ='Orcamento RU Viora Build'!C1007 -> 10 | D34: ='Orcamento RU Viora Build'!D1007 -> МЕТАЛЛОКОНСТРУКЦИИ И ОКОННЫЕ РАМЫ | J34: ='Orcamento RU Viora Build'!H1007 -> 268546.38 | L34: =+J34/$F$15 -> 683.67206
B35: ='Orcamento RU Viora Build'!C1394 -> 11 | D35: ='Orcamento RU Viora Build'!D1394 -> СТОЛЯРНЫЕ РАБОТЫ | J35: ='Orcamento RU Viora Build'!H1394 -> 60186.757 | L35: =+J35/$F$15 -> 153.22494
B36: ='Orcamento RU Viora Build'!C1554 -> 12 | D36: ='Orcamento RU Viora Build'!D1554 -> САНТЕХНИЧЕСКОЕ ОБОРУДОВАНИЕ | J36: ='Orcamento RU Viora Build'!H1554 -> 25273.269 | L36: =+J36/$F$15 -> 64.341316
B37: ='Orcamento RU Viora Build'!C1690 -> 13 | D37: ='Orcamento RU Viora Build'!D1690 -> ОБОРУДОВАНИЕ КУХНИ И ПРАЧЕЧНОЙ | J37: ='Orcamento RU Viora Build'!H1690 -> 4262.8398 | L37: =+J37/$F$15 -> 10.852443
B38: ='Orcamento RU Viora Build'!C1743 -> 14 | D38: ='Orcamento RU Viora Build'!D1743 -> ВНУТРЕННЯЯ СЕТЬ ВОДОСНАБЖЕНИЯ, БАССЕЙН | J38: ='Orcamento RU Viora Build'!H1743 -> 34663.27 | L38: =+J38/$F$15 -> 88.246613
B39: ='Orcamento RU Viora Build'!C1901 -> 15 | D39: ='Orcamento RU Viora Build'!D1901 -> ГАЗОВАЯ СЕТЬ | J39: ='Orcamento RU Viora Build'!H1901 -> 3640.6719 | L39: =+J39/$F$15 -> 9.268513
B40: ='Orcamento RU Viora Build'!C1934 -> 16 | D40: ='Orcamento RU Viora Build'!D1934 -> ПОСТАВКА И МОНТАЖ ОБОРУДОВАНИЯ И СИСТЕМ КОНДИЦИОНИРОВАНИЯ И ПРОИЗВОДСТВА ГОРЯЧЕЙ САНИТАРНОЙ ВОДЫ | J40: ='Orcamento RU Viora Build'!H1934 -> 131227.36 | L40: =+J40/$F$15 -> 334.08188
B41: ='Orcamento RU Viora Build'!C2221 -> 17 | D41: ='Orcamento RU Viora Build'!D2221 -> ЭЛЕКТРИЧЕСКАЯ СЕТЬ | J41: ='Orcamento RU Viora Build'!H2221 -> 121063.37 | L41: =+J41/$F$15 -> 308.20614
B42: ='Orcamento RU Viora Build'!C2682 -> 18 | D42: ='Orcamento RU Viora Build'!D2682 -> ТЕЛЕКОММУНИКАЦИОННЫЕ УСТАНОВКИ ITED | J42: ='Orcamento RU Viora Build'!H2682 -> 9916.335 | L42: =+J42/$F$15 -> 25.245252
B43: ='Orcamento RU Viora Build'!C2750 -> 19 | D43: ='Orcamento RU Viora Build'!D2750 -> ПОЛЫ, ПОКРЫТИЯ И СТРОИТЕЛЬНЫЕ ЭЛЕМЕНТЫ | J43: ='Orcamento RU Viora Build'!H2750 -> 25064.97 | L43: =+J43/$F$15 -> 63.811024
B44: ='Orcamento RU Viora Build'!C2819 -> 20 | D44: ='Orcamento RU Viora Build'!D2819 -> ОСВЕЩЕНИЕ - СВЕТОВЫЕ ТОЧКИ | J44: ='Orcamento RU Viora Build'!H2819 -> 0 | L44: =+J44/$F$15 -> 0
B45: ='Orcamento RU Viora Build'!C2840 -> 21 | D45: ='Orcamento RU Viora Build'!D2840 -> ОБОРУДОВАНИЕ | J45: ='Orcamento RU Viora Build'!H2840 -> 1396.226 | L45: =+J45/$F$15 -> 3.5545468
B46: ='Orcamento RU Viora Build'!C2852 -> 22 | D46: ='Orcamento RU Viora Build'!D2852 -> ПОСАДКИ И ПОСЕВЫ (ИСКЛЮЧЕН) | J46: ='Orcamento RU Viora Build'!H2852 -> 0 | L46: =+J46/$F$15 -> 0
B47: ='Orcamento RU Viora Build'!C2943 -> 23 | D47: ='Orcamento RU Viora Build'!D2943 -> ПОЛИВ (ИСКЛЮЧЕН) | J47: ='Orcamento RU Viora Build'!H2943 -> 0 | L47: =+J47/$F$15 -> 0
B48: ='Orcamento RU Viora Build'!C3014 -> 24 | D48: ='Orcamento RU Viora Build'!D3014 -> ОБСЛУЖИВАНИЕ ЗЕЛЕНЫХ ЗОН (ИСКЛЮЧЕН) | J48: ='Orcamento RU Viora Build'!H3014 -> 0 | L48: =+J48/$F$15 -> 0
B49: ='Orcamento RU Viora Build'!C3018 -> 25 | D49: ='Orcamento RU Viora Build'!D3018 -> БЛАГОУСТРОЙСТВО УЧАСТКА | J49: ='Orcamento RU Viora Build'!H3018 -> 44572.631 | L49: =+J49/$F$15 -> 113.47411
B50: ='Orcamento RU Viora Build'!C3123 -> 26 | D50: ='Orcamento RU Viora Build'!D3123 -> ПРОЧЕЕ | J50: ='Orcamento RU Viora Build'!H3123 -> 12030.2 | L50: =+J50/$F$15 -> 30.626782
B51: ='Orcamento RU Viora Build'!C3167 -> 27 | D51: ='Orcamento RU Viora Build'!D3167 -> ВНУТРЕННЯЯ СЕТЬ БЫТОВЫХ И ДОЖДЕВЫХ СТОЧНЫХ ВОД | J51: ='Orcamento RU Viora Build'!H3167 -> 47244.964 | L51: =+J51/$F$15 -> 120.2774
B53: ИТОГО ЗА ЖИЛЬЕ | J53: =SUM(J25:J51) -> 1708318.9 | L53: =+J53/$F$15 -> 4349.0807
B54: IVA (23%) | J54: =+J53*0.23 -> 392913.35
B55: ИТОГО С IVA | J55: =+J54+J53 -> 2101232.2
B57: ИТОГО ЗА БАССЕЙН | L57: =+J57/$F$19 -> 0
...

Sheet Orcamento RU Viora Build
A1: ID | B1: № M | C1: № V | D1: ОПИСАНИЕ РАБОТ | E1: ЕД. ИЗМ. | F1: КОЛ-ВО | G1: ЦЕНА ЗА ЕДИНИЦУ | H1: ОБЩАЯ СТОИМОСТЬ | I1: Коментарий
I2: Matthew ENG
C4: 1 | D4: СТРОИТЕЛЬНАЯ ПЛОЩАДКА И ДОПОЛНИТЕЛЬНЫЕ РАБОТЫ | E4: =H8 | H4: =SUM(H10:H52) -> 2015 | I4: =H4-('Orcamento RU'!C4+'Orcamento RU'!C2206) -> -176195.4
D6: СТРОИТЕЛЬНАЯ ПЛОЩАДКА | G6: =SUM(H10:H38) -> 2015
B8: 1.1.1 (1) | C8: 1.1 | D8: Монтаж, строительство, обслуживание, демонтаж и снос строительной площадки, включая соответствующие установки, временные сети водоснабжения, канализации, электричества и средства телекоммуникаций, внутренние пути движения и все остальное необходимое в соответствии с Декретом-Законом № 18/08 от 29 января, удовлетворяющее предписаниям по безопасности, гигиене и охране труда, в соответствии с Декретом-Законом № 273/2003 от 29 октября и прочим действующим законодательством, разработка и внедрение плана предотвращения и управления отходами строительства и сноса (в понимании Д.З. № 46/2008 от 12 марта).
A10: ='Master List'!A463 -> W-PRE-001 | B10: 1.1.1 (1) | C10: 1.1.1 | D10: =VLOOKUP(A10,'Master List'!$A$1:$C$1192,2,FALSE) -> Поставка и установка, обслуживание и демонтаж ограждения вокруг участка с непрозрачными панелями из профилированного оцинкованного стального листа толщиной 0,6 мм, с ребрами высотой от 40 до 50 мм, расположенными на расстоянии от 250 до 270 мм, и профилями в S из согнутого оцинкованного стального листа размером 102x33x1,5 мм, с отделкой сендзимир, длиной 2,8 м, закрепленными в земле с помощью кубов бетона C20/25 XC0 Cl0.40 Dmax 25mm S2 размером 102x33x1,5 см, каждые 2,0 м, включая все работы и материалы, которые к ним относятся. | E10: =VLOOKUP(A10,'Master List'!$A$1:$C$1192,3,FALSE) -> м | F10: 0 | G10: =VLOOKUP(A10,'Master List'!$A$4:$F2715,5,FALSE) -> 106750.8 | H10: =G10*F10 -> 0 | I10: Matthew сообщил, что, по словам архитектора, временный забор по периметру дома не требуется. Он понадобится только в зоне въезда. Ранее у нас было заложено 260 погонных метров по цене 100 евро за метр. Мы согласовали, что при необходимости можно будет сразу строить постоянный забор вместо временного — это позволит сэкономить 26 000 евро. Если же всё-таки будет принято решение установить временный забор во фронтальной части, его стоимость составит 100 евро за погонный метр.
A12: ='Master List'!A464 -> W-PRE-002 | B12: 1.1.1 (1) | C12: 1.1.2 | D12: =VLOOKUP(A12,'Master List'!$A$1:$C$1192,2,FALSE) -> Поставка и монтаж, обслуживание и разборка раздвижных ворот для доступа транспортных средств из оцинкованной стали из двух створок с приблизительными размерами 4,0x2,0м с защелкой для замка и фурнитурой для крепления к полу, установленные в временном ограждении территории, закрепленные с помощью столбов из того же материала, анкерованных в грунте с помощью бетонных кубов C20/25 XC0 Cl0.40 Dmáx 25mm S2, включая все работы и материалы, связанные с этим. | E12: =VLOOKUP(A12,'Master List'!$A$1:$C$1192,3,FALSE) -> шт | F12: 1 | G12: =VLOOKUP(A12,'Master List'!$A$4:$F2717,5,FALSE) -> 1560 | H12: =G12*F12 -> 1560
A14: ='Master List'!A465 -> W-PRE-003 | B14: 1.1.1 (1) | C14: 1.1.3 | D14: =VLOOKUP(A14,'Master List'!$A$1:$C$1192,2,FALSE) -> Поставка и установка информационного щита, рекламирующего строительство, включая все работы и материалы, относящиеся к этому. | E14: =VLOOKUP(A14,'Master List'!$A$1:$C$1192,3,FALSE) -> шт | F14: 1 | G14: =VLOOKUP(A14,'Master List'!$A$4:$F2719,5,FALSE) -> 455 | H14: =G14*F14 -> 455
A16: ='Master List'!A466 -> W-PRE-004 | B16: 1.1.1 (1) | C16: 1.1.4 | D16: =VLOOKUP(A16,'Master List'!$A$1:$C$1192,2,FALSE) -> Поставка и выполнение первичных сетей электричества, воды и канализации, включая ежемесячное потребление в течение всего срока выполнения работ до предварительного приемки, включая связанные работы и материалы. | E16: =VLOOKUP(A16,'Master List'!$A$1:$C$1192,3,FALSE) -> міс | F16: 18 | G16: =VLOOKUP(A16,'Master List'!$A$4:$F2721,5,FALSE) -> 0 | H16: =G16*F16 -> 0 | I16: Этот пункт будет урегулироваться по факту
A18: ='Master List'!A467 -> W-PRE-005 | B18: 1.1.1 (1) | C18: 1.1.5 | D18: =VLOOKUP(A18,'Master List'!$A$1:$C$1192,2,FALSE) -> Поставка и монтаж офисного модуля размером 6,0x3,0 м для строительных совещаний, установленного на выровненной основе из щебня, с туалетом и кондиционером, включая заземление и все сопутствующие работы и материалы. | E18: =VLOOKUP(A18,'Master List'!$A$1:$C$1192,3,FALSE) -> шт | F18: 1 | G18: =VLOOKUP(A18,'Master List'!$A$4:$F2723,5,FALSE) -> 0 | H18: =G18*F18 -> 0 | I18: По желанию клиента для его удобства. Цена 12 000 Евро
A20: ='Master List'!A468 -> W-PRE-006 | B20: 1.1.1 (1) | C20: 1.1.6 | D20: =VLOOKUP(A20,'Master List'!$A$1:$C$1192,2,FALSE) -> Поставка и монтаж модуля общего инструмента размером 3,0x2,40 м типа морского контейнера, установленного на выровненной основе из щебня, включая все работы и материалы, связанные с этим. | E20: =VLOOKUP(A20,'Master List'!$A$1:$C$1192,3,FALSE) -> шт | F20: 1 | G20: =VLOOKUP(A20,'Master List'!$A$4:$F2725,5,FALSE) -> 0 | H20: =G20*F20 -> 0
A22: ='Master List'!A469 -> W-PRE-007 | B22: 1.1.1 (1) | C22: 1.1.7 | D22: =VLOOKUP(A22,'Master List'!$A$1:$C$1192,2,FALSE) -> Поставка и установка портативного санитарного блока из полиэтилена размером 1,20x1,20x2,35м серого цвета или другого, без подключений, с анаэробным химическим туалетом с системой сброса на ножном приводе, зеркалом, дверью с замком и полупрозрачным потолком для пропуска внешнего света, включая еженедельную уборку и все сопутствующие работы и материалы. | E22: =VLOOKUP(A22,'Master List'!$A$1:$C$1192,3,FALSE) -> міс | F22: 18 | G22: =VLOOKUP(A22,'Master List'!$A$4:$F2727,5,FALSE) -> 0 | H22: =G22*F22 -> 0
A24: ='Master List'!A470 -> W-PRE-008 | B24: 1.1.1 (1) | C24: 1.8 | D24: =VLOOKUP(A24,'Master List'!$A$1:$C$1192,2,FALSE) -> Поставка и выполнение топографической разбивки через специализированного техника уровней установки строительства, включая бассейн и границы, а также все работы и материалы, связанные с этим. | E24: =VLOOKUP(A24,'Master List'!$A$1:$C$1192,3,FALSE) -> шт | F24: 1 | G24: =VLOOKUP(A24,'Master List'!$A$4:$F2729,5,FALSE) -> 0 | H24: =G24*F24 -> 0
A26: ='Master List'!A471 -> W-PRE-009 | B26: 1.1.1 (1) | C26: 1.9 | D26: =VLOOKUP(A26,'Master List'!$A$1:$C$1192,2,FALSE) -> Поставка и монтаж строительных лесов из стандартных труб, многофункционального типа, высотой до 9 м, состоящих из стальной трубной конструкции из горячекатаной оцинкованной стали диаметром 48,3 мм и толщиной 3,2 мм, без дублирования вертикальных элементов, состоящих из рабочих платформ шириной 60 см, размещенных каждые 2 м по высоте, внутренней лестницы с люком, задних ограждений с двумя перекладинами и нижней планкой, и передних ограждений с одной перекладиной, для выполнения фасада(ов) с конструктивными элементами (крытые и открытые террасы, карнизы и другие и т. д.), размещенными на более чем 50% их периметра и выступающими более чем на 30 см от плоскости фасада. Примечание (1): строительные леса должны полностью соответствовать действующему законодательству, в частности, EN 12811 и EN 12810. | E26: =VLOOKUP(A26,'Master List'!$A$1:$C$1192,3,FALSE) -> міс | F26: 18 | G26: =VLOOKUP(A26,'Master List'!$A$4:$F2731,5,FALSE) -> 0 | H26: =G26*F26 -> 0 | I26: Аренда строительных лесов
A28: ='Master List'!A472 -> W-PRE-010 | B28: 1.1.1 (1) | C28: 1.10 | D28: =VLOOKUP(A28,'Master List'!$A$1:$C$1192,2,FALSE) -> Поставка, выполнение и внедрение/адаптация плана безопасности и здоровья (ПБЗ) на этапе строительства, включая все работы и материалы, связанные с этим. | E28: =VLOOKUP(A28,'Master List'!$A$1:$C$1192,3,FALSE) -> міс | F28: 18 | G28: =VLOOKUP(A28,'Master List'!$A$4:$F2733,5,FALSE) -> 0 | H28: =G28*F28 -> 0 | I28: Страховка обьекта может отличаться от 300-500 евро. Написали последнюю информацию
A30: ='Master List'!A473 -> W-PRE-011 | B30: 1.1.1 (1) | C30: 1.11 | D30: =VLOOKUP(A30,'Master List'!$A$1:$C$1192,2,FALSE) -> Поставка, выполнение и внедрение/адаптация плана управления отходами (ПГО), его классификация (ЛЕР), сортировка и разделение на его перерабатываемые компоненты и соответствующая утилизация или транспортировка в зоны переработки и к уполномоченным и лицензированным операторам, в соответствии с действующим законодательством. | E30: =VLOOKUP(A30,'Master List'!$A$1:$C$1192,3,FALSE) -> міс | F30: 18 | G30: =VLOOKUP(A30,'Master List'!$A$4:$F2735,5,FALSE) -> 0 | H30: =G30*F30 -> 0 | I30: Этот пункт будет урегулироваться по факту
A32: ='Master List'!A474 -> W-PRE-012 | B32: 1.1.1 (1) | C32: 1.12 | D32: =VLOOKUP(A32,'Master List'!$A$1:$C$1192,2,FALSE) -> Подготовка и передача владельцу строительного проекта технической компиляции работ, которая включает полезные элементы, которые следует учитывать при их будущем использовании, а также работы, выполняемые после их завершения для сохранения безопасности и здоровья тех, кто их выполняет, в соответствии с положениями статьи 16 Декрета-Закона № 273/2003 от 29 октября, с учетом итоговых чертежей всех специальностей на бумажном и цифровом носителе, всех исследований, проектов, сопутствующей и связанной документации. | E32: =VLOOKUP(A32,'Master List'!$A$1:$C$1192,3,FALSE) -> шт | F32: 1 | G32: =VLOOKUP(A32,'Master List'!$A$4:$F2737,5,FALSE) -> 0 | H32: =G32*F32 -> 0 | I32: Входить в стоимость самого проекта
A34: ='Master List'!A475 -> W-PRE-013 | B34: 1.1.1 (1) | C34: 1.13 | D34: =VLOOKUP(A34,'Master List'!$A$1:$C$1192,2,FALSE) -> Обеспечение и координация человеческих и материальных ресурсов, необходимых для уборки и обслуживания строительной площадки, включая установку всего оборудования безопасности, такого как ограждения и линии жизни и т.д., все в соответствии с действующим законодательством. | E34: =VLOOKUP(A34,'Master List'!$A$1:$C$1192,3,FALSE) -> міс | F34: 18 | G34: =VLOOKUP(A34,'Master List'!$A$4:$F2739,5,FALSE) -> 0 | H34: =G34*F34 -> 0
A36: ='Master List'!A476 -> W-PRE-014 | B36: 1.1.1 (1) | C36: 1.14 | D36: =VLOOKUP(A36,'Master List'!$A$1:$C$1192,2,FALSE) -> Поставка специализированного персонала, а именно директора проекта (гражданский инженер), главного прораба, подготовителя проекта. | E36: =VLOOKUP(A36,'Master List'!$A$1:$C$1192,3,FALSE) -> міс | F36: 18 | G36: =VLOOKUP(A36,'Master List'!$A$4:$F2741,5,FALSE) -> 0 | H36: =G36*F36 -> 0
A38: ='Master List'!A477 -> W-PRE-015 | B38: 1.1.1 (1) | C38: 1.15 | D38: =VLOOKUP(A38,'Master List'!$A$1:$C$1192,2,FALSE) -> Поставка и установка оборудования и материалов безопасности, расположенных в видимых местах, включая все работы и материалы, связанные с этим. | E38: =VLOOKUP(A38,'Master List'!$A$1:$C$1192,3,FALSE) -> шт | F38: 1 | G38: =VLOOKUP(A38,'Master List'!$A$4:$F2743,5,FALSE) -> 0 | H38: =G38*F38 -> 0
D40: КРАН | G40: =SUM(H42:H52) -> 0
A42: ='Master List'!A478 -> W-PRE-016 | C42: 1.16 | D42: =VLOOKUP(A42,'Master List'!$A$1:$C$1192,2,FALSE) -> Поставка и выполнение земляных работ на любом типе грунта для основания крана, включая укладку земли в хранилище для насыпей, уплотнение и выравнивание основания рабочей платформы, а также все работы и материалы, связанные с этим. | E42: =VLOOKUP(A42,'Master List'!$A$1:$C$1192,3,FALSE) -> шт | F42: 1 | G42: =VLOOKUP(A42,'Master List'!$A$4:$F2747,5,FALSE) -> 0 | H42: =G42*F42 -> 0 | I42: Включено в стоимость земелных работ
A44: ='Master List'!A479 -> W-PRE-017 | C44: 1.17 | D44: =VLOOKUP(A44,'Master List'!$A$1:$C$1192,2,FALSE) -> Поставка и выполнение элементов бетонной конструкции типа C25/30 XC2(P) Dmáx 20mm S3, изготовленных, транспортированных и уложенных на объекте в соответствии с NP EN 206-1 и NP ENV 13670-1 для основания установки крана, включая выполнение опалубки и арматур из стали типа A500NR SD и все работы, необходимые для качественной отделки, всё в соответствии с проектом устойчивости, включая все работы и материалы, связанные с этим. Примечание (1): необходимо учитывать демонтаж фундамента крана. | E44: =VLOOKUP(A44,'Master List'!$A$1:$C$1192,3,FALSE) -> шт | F44: 1 | G44: =VLOOKUP(A44,'Master List'!$A$4:$F2749,5,FALSE) -> 0 | H44: =G44*F44 -> 0
C46: 1.18 | D46: Поставка и эксплуатация башенного крана с выдвижной стрелой длиной 50 м с характеристиками, соответствующими объекту, включая радиоуправление и управление по кабелю, ковш-санки на 300 литров и поддон для 2000 кг. | E46: vg | F46: 1
A48: ='Master List'!A480 -> W-PRE-018 | C48: 1.18.1 | D48: =VLOOKUP(A48,'Master List'!$A$1:$C$1192,2,FALSE) -> Монтаж крана | E48: =VLOOKUP(A48,'Master List'!$A$1:$C$1192,3,FALSE) -> шт | F48: 1 | G48: =VLOOKUP(A48,'Master List'!$A$4:$F2753,5,FALSE) -> 0 | H48: =G48*F48 -> 0
